2019-01-14 11:38:20,297 INFO: Microblog startup [in C:\Users\rokotyansky.n.1\Documents\Projects\micro-blog\app\__init__.py:44]
2019-01-14 11:38:34,561 ERROR: Exception on /edit_profile [POST] [in C:\Users\rokotyansky.n.1\Documents\Projects\micro-blog\venv\lib\site-packages\flask\app.py:1761]
Traceback (most recent call last):
  File "C:\Users\rokotyansky.n.1\Documents\Projects\micro-blog\venv\lib\site-packages\sqlalchemy\engine\base.py", line 1230, in _execute_context
    cursor, statement, parameters, context
  File "C:\Users\rokotyansky.n.1\Documents\Projects\micro-blog\venv\lib\site-packages\sqlalchemy\engine\default.py", line 536, in do_execute
    cursor.execute(statement, parameters)
sqlite3.IntegrityError: UNIQUE constraint failed: user.username

The above exception was the direct cause of the following exception:

Traceback (most recent call last):
  File "C:\Users\rokotyansky.n.1\Documents\Projects\micro-blog\venv\lib\site-packages\flask\app.py", line 2292, in wsgi_app
    response = self.full_dispatch_request()
  File "C:\Users\rokotyansky.n.1\Documents\Projects\micro-blog\venv\lib\site-packages\flask\app.py", line 1815, in full_dispatch_request
    rv = self.handle_user_exception(e)
  File "C:\Users\rokotyansky.n.1\Documents\Projects\micro-blog\venv\lib\site-packages\flask\app.py", line 1718, in handle_user_exception
    reraise(exc_type, exc_value, tb)
  File "C:\Users\rokotyansky.n.1\Documents\Projects\micro-blog\venv\lib\site-packages\flask\_compat.py", line 35, in reraise
    raise value
  File "C:\Users\rokotyansky.n.1\Documents\Projects\micro-blog\venv\lib\site-packages\flask\app.py", line 1813, in full_dispatch_request
    rv = self.dispatch_request()
  File "C:\Users\rokotyansky.n.1\Documents\Projects\micro-blog\venv\lib\site-packages\flask\app.py", line 1799, in dispatch_request
    return self.view_functions[rule.endpoint](**req.view_args)
  File "C:\Users\rokotyansky.n.1\Documents\Projects\micro-blog\venv\lib\site-packages\flask_login\utils.py", line 261, in decorated_view
    return func(*args, **kwargs)
  File "C:\Users\rokotyansky.n.1\Documents\Projects\micro-blog\app\routes.py", line 100, in edit_profile
    db.session.commit()
  File "C:\Users\rokotyansky.n.1\Documents\Projects\micro-blog\venv\lib\site-packages\sqlalchemy\orm\scoping.py", line 162, in do
    return getattr(self.registry(), name)(*args, **kwargs)
  File "C:\Users\rokotyansky.n.1\Documents\Projects\micro-blog\venv\lib\site-packages\sqlalchemy\orm\session.py", line 1008, in commit
    self.transaction.commit()
  File "C:\Users\rokotyansky.n.1\Documents\Projects\micro-blog\venv\lib\site-packages\sqlalchemy\orm\session.py", line 487, in commit
    self._prepare_impl()
  File "C:\Users\rokotyansky.n.1\Documents\Projects\micro-blog\venv\lib\site-packages\sqlalchemy\orm\session.py", line 466, in _prepare_impl
    self.session.flush()
  File "C:\Users\rokotyansky.n.1\Documents\Projects\micro-blog\venv\lib\site-packages\sqlalchemy\orm\session.py", line 2424, in flush
    self._flush(objects)
  File "C:\Users\rokotyansky.n.1\Documents\Projects\micro-blog\venv\lib\site-packages\sqlalchemy\orm\session.py", line 2562, in _flush
    transaction.rollback(_capture_exception=True)
  File "C:\Users\rokotyansky.n.1\Documents\Projects\micro-blog\venv\lib\site-packages\sqlalchemy\util\langhelpers.py", line 67, in __exit__
    compat.reraise(exc_type, exc_value, exc_tb)
  File "C:\Users\rokotyansky.n.1\Documents\Projects\micro-blog\venv\lib\site-packages\sqlalchemy\util\compat.py", line 277, in reraise
    raise value
  File "C:\Users\rokotyansky.n.1\Documents\Projects\micro-blog\venv\lib\site-packages\sqlalchemy\orm\session.py", line 2522, in _flush
    flush_context.execute()
  File "C:\Users\rokotyansky.n.1\Documents\Projects\micro-blog\venv\lib\site-packages\sqlalchemy\orm\unitofwork.py", line 416, in execute
    rec.execute(self)
  File "C:\Users\rokotyansky.n.1\Documents\Projects\micro-blog\venv\lib\site-packages\sqlalchemy\orm\unitofwork.py", line 583, in execute
    uow,
  File "C:\Users\rokotyansky.n.1\Documents\Projects\micro-blog\venv\lib\site-packages\sqlalchemy\orm\persistence.py", line 236, in save_obj
    update,
  File "C:\Users\rokotyansky.n.1\Documents\Projects\micro-blog\venv\lib\site-packages\sqlalchemy\orm\persistence.py", line 976, in _emit_update_statements
    statement, multiparams
  File "C:\Users\rokotyansky.n.1\Documents\Projects\micro-blog\venv\lib\site-packages\sqlalchemy\engine\base.py", line 974, in execute
    return meth(self, multiparams, params)
  File "C:\Users\rokotyansky.n.1\Documents\Projects\micro-blog\venv\lib\site-packages\sqlalchemy\sql\elements.py", line 273, in _execute_on_connection
    return connection._execute_clauseelement(self, multiparams, params)
  File "C:\Users\rokotyansky.n.1\Documents\Projects\micro-blog\venv\lib\site-packages\sqlalchemy\engine\base.py", line 1093, in _execute_clauseelement
    distilled_params,
  File "C:\Users\rokotyansky.n.1\Documents\Projects\micro-blog\venv\lib\site-packages\sqlalchemy\engine\base.py", line 1234, in _execute_context
    e, statement, parameters, cursor, context
  File "C:\Users\rokotyansky.n.1\Documents\Projects\micro-blog\venv\lib\site-packages\sqlalchemy\engine\base.py", line 1452, in _handle_dbapi_exception
    util.raise_from_cause(sqlalchemy_exception, exc_info)
  File "C:\Users\rokotyansky.n.1\Documents\Projects\micro-blog\venv\lib\site-packages\sqlalchemy\util\compat.py", line 296, in raise_from_cause
    reraise(type(exception), exception, tb=exc_tb, cause=cause)
  File "C:\Users\rokotyansky.n.1\Documents\Projects\micro-blog\venv\lib\site-packages\sqlalchemy\util\compat.py", line 276, in reraise
    raise value.with_traceback(tb)
  File "C:\Users\rokotyansky.n.1\Documents\Projects\micro-blog\venv\lib\site-packages\sqlalchemy\engine\base.py", line 1230, in _execute_context
    cursor, statement, parameters, context
  File "C:\Users\rokotyansky.n.1\Documents\Projects\micro-blog\venv\lib\site-packages\sqlalchemy\engine\default.py", line 536, in do_execute
    cursor.execute(statement, parameters)
sqlalchemy.exc.IntegrityError: (sqlite3.IntegrityError) UNIQUE constraint failed: user.username [SQL: 'UPDATE user SET username=?, about_me=? WHERE user.id = ?'] [parameters: ('susan', 'My life fo Aur', 3)] (Background on this error at: http://sqlalche.me/e/gkpj)
2019-01-14 11:46:04,612 INFO: Microblog startup [in C:\Users\rokotyansky.n.1\Documents\Projects\micro-blog\app\__init__.py:44]
2019-01-15 11:24:45,711 INFO: Microblog startup [in C:\Users\rokotyansky.n.1\Documents\Projects\micro-blog\app\__init__.py:44]
2019-01-15 11:25:09,783 INFO: Microblog startup [in C:\Users\rokotyansky.n.1\Documents\Projects\micro-blog\app\__init__.py:44]
2019-01-15 11:26:55,564 INFO: Microblog startup [in C:\Users\rokotyansky.n.1\Documents\Projects\micro-blog\app\__init__.py:44]
2019-01-15 11:30:16,285 INFO: Microblog startup [in C:\Users\rokotyansky.n.1\Documents\Projects\micro-blog\app\__init__.py:44]
2019-01-15 11:31:31,430 INFO: Microblog startup [in C:\Users\rokotyansky.n.1\Documents\Projects\micro-blog\app\__init__.py:44]
2019-01-15 11:32:35,903 INFO: Microblog startup [in C:\Users\rokotyansky.n.1\Documents\Projects\micro-blog\app\__init__.py:44]
2019-01-15 11:35:39,677 INFO: Microblog startup [in C:\Users\rokotyansky.n.1\Documents\Projects\micro-blog\app\__init__.py:44]
2019-01-15 11:38:17,542 INFO: Microblog startup [in C:\Users\rokotyansky.n.1\Documents\Projects\micro-blog\app\__init__.py:44]
2019-01-15 11:39:06,550 INFO: Microblog startup [in C:\Users\rokotyansky.n.1\Documents\Projects\micro-blog\app\__init__.py:44]
2019-01-15 13:44:20,721 INFO: Microblog startup [in C:\Users\rokotyansky.n.1\Documents\Projects\micro-blog\app\__init__.py:44]
2019-01-15 13:46:06,855 INFO: Microblog startup [in C:\Users\rokotyansky.n.1\Documents\Projects\micro-blog\app\__init__.py:44]
2019-01-15 13:48:29,397 INFO: Microblog startup [in C:\Users\rokotyansky.n.1\Documents\Projects\micro-blog\app\__init__.py:44]
2019-01-15 13:48:38,505 INFO: Microblog startup [in C:\Users\rokotyansky.n.1\Documents\Projects\micro-blog\app\__init__.py:44]
2019-01-15 13:48:50,967 INFO: Microblog startup [in C:\Users\rokotyansky.n.1\Documents\Projects\micro-blog\app\__init__.py:44]
2019-01-15 13:53:59,209 INFO: Microblog startup [in C:\Users\rokotyansky.n.1\Documents\Projects\micro-blog\app\__init__.py:44]
